2025-04-23 11:46:52 - INFO - Default parameters: {'train_file': 'input data/dev.csv', 'validation_file': 'input data/oos.csv', 'test_file': 'input data/oot.csv', 'target_column': 'Class', 'drop_features': 'no', 'train_on': 'normal', 'feature_selection': 'fpi', 'feature_threshold': 0.1, 'model_threshold': 0.5, 'model': 'LogisticRegression', 'cross_validation': 5, 'autoencoder': {'ratios': [0.8, 0.5, 0.2], 'epochs': 10, 'batch_size': 32, 'dropout': 0.1, 'hidden_activation': 'selu', 'optimizer': 'adam', 'loss': 'mse'}, 'model_params': {'C': 1.0, 'penalty': 'l2', 'solver': 'lbfgs', 'max_iter': 200, 'random_state': 42}}
2025-04-23 11:46:52 - INFO - Running initial feature selection using default parameters
2025-04-23 11:48:25 - INFO - Default parameters: {'train_file': 'input data/dev.csv', 'validation_file': 'input data/oos.csv', 'test_file': 'input data/oot.csv', 'target_column': 'Class', 'drop_features': 'no', 'train_on': 'normal', 'feature_selection': 'fpi', 'feature_threshold': 0.1, 'model_threshold': 0.5, 'model': 'LogisticRegression', 'cross_validation': 5, 'autoencoder': {'ratios': [0.8, 0.5, 0.2], 'epochs': 10, 'batch_size': 32, 'dropout': 0.1, 'hidden_activation': 'selu', 'optimizer': 'adam', 'loss': 'mse'}, 'model_params': {'C': 1.0, 'penalty': 'l2', 'solver': 'lbfgs', 'max_iter': 200, 'random_state': 42}}
2025-04-23 11:48:25 - INFO - Running initial feature selection using default parameters
2025-04-23 21:35:53 - INFO - Default parameters: {'train_file': 'input data/dev.csv', 'validation_file': 'input data/oos.csv', 'test_file': 'input data/oot.csv', 'target_column': 'Class', 'drop_features': 'no', 'train_on': 'normal', 'feature_selection': 'fpi', 'feature_threshold': 0.1, 'model_threshold': 0.5, 'model': 'LogisticRegression', 'cross_validation': 5, 'autoencoder': {'ratios': [0.8, 0.5, 0.2], 'epochs': 10, 'batch_size': 32, 'dropout': 0.1, 'hidden_activation': 'selu', 'optimizer': 'adam', 'loss': 'mse'}, 'model_params': {'C': 1.0, 'penalty': 'l2', 'solver': 'lbfgs', 'max_iter': 200, 'random_state': 42}}
2025-04-23 21:35:53 - INFO - Running initial feature selection using default parameters
2025-04-23 21:38:12 - INFO - Feature selection completed. Dropped features: ['V1', 'V5', 'V9', 'V15', 'V19', 'V20', 'V24', 'V26']
2025-04-24 17:44:32 - INFO - Default parameters: {'train_file': 'input data/dev.csv', 'validation_file': 'input data/oos.csv', 'test_file': 'input data/oot.csv', 'target_column': 'Class', 'drop_features': 'no', 'train_on': 'normal', 'feature_selection': 'fpi', 'feature_threshold': 0.1, 'model_threshold': 0.5, 'model': 'LogisticRegression', 'cross_validation': 5, 'autoencoder': {'ratios': [0.8, 0.5, 0.2], 'epochs': 10, 'batch_size': 32, 'dropout': 0.1, 'hidden_activation': 'selu', 'optimizer': 'adam', 'loss': 'mse'}}
2025-04-24 17:44:32 - INFO - Running initial feature selection using default parameters
2025-04-24 17:47:27 - INFO - Feature selection completed. Dropped features: ['V1', 'V4', 'V9', 'V10', 'V11', 'V12', 'V14', 'V20', 'V22', 'V25', 'V26', 'Amount']
2025-04-24 18:02:33 - INFO - Default parameters: {'train_file': 'input data/dev.csv', 'validation_file': 'input data/oos.csv', 'test_file': 'input data/oot.csv', 'target_column': 'Class', 'drop_features': 'no', 'train_on': 'normal', 'feature_selection': 'fpi', 'feature_threshold': 0.1, 'model_threshold': 0.5, 'model': 'LogisticRegression', 'cross_validation': 5, 'autoencoder': {'ratios': [0.8, 0.5, 0.2], 'epochs': 10, 'batch_size': 32, 'dropout': 0.1, 'hidden_activation': 'selu', 'optimizer': 'adam', 'loss': 'mse'}}
2025-04-24 18:02:33 - INFO - Running initial feature selection using default parameters
2025-04-24 18:08:09 - INFO - Default parameters: {'train_file': 'input data/dev.csv', 'validation_file': 'input data/oos.csv', 'test_file': 'input data/oot.csv', 'target_column': 'Class', 'drop_features': 'no', 'train_on': 'normal', 'feature_selection': 'fpi', 'feature_threshold': 0.1, 'model_threshold': 0.5, 'model': 'LogisticRegression', 'cross_validation': 5, 'autoencoder': {'ratios': [0.8, 0.5, 0.2], 'epochs': 10, 'batch_size': 32, 'dropout': 0.1, 'hidden_activation': 'selu', 'optimizer': 'adam', 'loss': 'mse'}}
2025-04-24 18:08:09 - INFO - Running initial feature selection using default parameters
2025-04-24 18:11:04 - ERROR - Error during feature selection: [Errno 2] No such file or directory: 'input_data/dev.csv'
2025-04-24 18:11:04 - ERROR - Traceback (most recent call last):
  File "c:\Users\prana\OneDrive\Desktop\Application\run_fs.py", line 26, in <module>
    features_dropped = fs(default_hyperparameters)
                       ^^^^^^^^^^^^^^^^^^^^^^^^^^^
  File "c:\Users\prana\OneDrive\Desktop\Application\pipeline.py", line 71, in fs
    log_metrics_and_artifacts(
  File "c:\Users\prana\OneDrive\Desktop\Application\mlflow_utils.py", line 35, in log_metrics_and_artifacts
    mlflow.log_artifact("input_data/dev.csv", "datasets")
  File "C:\Users\prana\AppData\Local\Programs\Python\Python312\Lib\site-packages\mlflow\tracking\fluent.py", line 1179, in log_artifact
    MlflowClient().log_artifact(run_id, local_path, artifact_path)
  File "C:\Users\prana\AppData\Local\Programs\Python\Python312\Lib\site-packages\mlflow\tracking\client.py", line 2374, in log_artifact
    self._tracking_client.log_artifact(run_id, local_path, artifact_path)
  File "C:\Users\prana\AppData\Local\Programs\Python\Python312\Lib\site-packages\mlflow\tracking\_tracking_service\client.py", line 926, in log_artifact
    artifact_repo.log_artifact(local_path, artifact_path)
  File "C:\Users\prana\AppData\Local\Programs\Python\Python312\Lib\site-packages\mlflow\store\artifact\http_artifact_repo.py", line 62, in log_artifact
    with open(local_file, "rb") as f:
         ^^^^^^^^^^^^^^^^^^^^^^
FileNotFoundError: [Errno 2] No such file or directory: 'input_data/dev.csv'

2025-04-24 18:17:48 - INFO - Default parameters: {'train_file': 'input data/dev.csv', 'validation_file': 'input data/oos.csv', 'test_file': 'input data/oot.csv', 'target_column': 'Class', 'drop_features': 'no', 'train_on': 'normal', 'feature_selection': 'fpi', 'feature_threshold': 0.1, 'model_threshold': 0.5, 'model': 'LogisticRegression', 'cross_validation': 5, 'autoencoder': {'ratios': [0.8, 0.5, 0.2], 'epochs': 10, 'batch_size': 32, 'dropout': 0.1, 'hidden_activation': 'selu', 'optimizer': 'adam', 'loss': 'mse'}}
2025-04-24 18:17:48 - INFO - Running initial feature selection using default parameters
2025-04-24 18:20:58 - ERROR - Error during feature selection: [Errno 2] No such file or directory: 'input_data/dev.csv'
2025-04-24 18:20:58 - ERROR - Traceback (most recent call last):
  File "c:\Users\prana\OneDrive\Desktop\Application\run_fs.py", line 26, in <module>
    features_dropped = fs(default_hyperparameters)
                       ^^^^^^^^^^^^^^^^^^^^^^^^^^^
  File "c:\Users\prana\OneDrive\Desktop\Application\pipeline.py", line 71, in fs
    log_metrics_and_artifacts(
  File "c:\Users\prana\OneDrive\Desktop\Application\mlflow_utils.py", line 35, in log_metrics_and_artifacts
    mlflow.log_artifact("input_data/dev.csv", "datasets")
  File "C:\Users\prana\AppData\Local\Programs\Python\Python312\Lib\site-packages\mlflow\tracking\fluent.py", line 1179, in log_artifact
    MlflowClient().log_artifact(run_id, local_path, artifact_path)
  File "C:\Users\prana\AppData\Local\Programs\Python\Python312\Lib\site-packages\mlflow\tracking\client.py", line 2374, in log_artifact
    self._tracking_client.log_artifact(run_id, local_path, artifact_path)
  File "C:\Users\prana\AppData\Local\Programs\Python\Python312\Lib\site-packages\mlflow\tracking\_tracking_service\client.py", line 926, in log_artifact
    artifact_repo.log_artifact(local_path, artifact_path)
  File "C:\Users\prana\AppData\Local\Programs\Python\Python312\Lib\site-packages\mlflow\store\artifact\http_artifact_repo.py", line 62, in log_artifact
    with open(local_file, "rb") as f:
         ^^^^^^^^^^^^^^^^^^^^^^
FileNotFoundError: [Errno 2] No such file or directory: 'input_data/dev.csv'

2025-04-24 18:36:14 - INFO - Default parameters: {'train_file': 'input data/dev.csv', 'validation_file': 'input data/oos.csv', 'test_file': 'input data/oot.csv', 'target_column': 'Class', 'drop_features': 'no', 'train_on': 'normal', 'feature_selection': 'fpi', 'feature_threshold': 0.1, 'model_threshold': 0.5, 'model': 'LogisticRegression', 'cross_validation': 5, 'autoencoder': {'ratios': [0.8, 0.5, 0.2], 'epochs': 10, 'batch_size': 32, 'dropout': 0.1, 'hidden_activation': 'selu', 'optimizer': 'adam', 'loss': 'mse'}}
2025-04-24 18:36:14 - INFO - Running initial feature selection using default parameters
2025-04-24 18:36:17 - ERROR - Error during feature selection: Run with UUID 643a82c13224408281a57325fc8e5998 is already active. To start a new run, first end the current run with mlflow.end_run(). To start a nested run, call start_run with nested=True
2025-04-24 18:36:17 - ERROR - Traceback (most recent call last):
  File "c:\Users\prana\OneDrive\Desktop\Application\run_fs.py", line 35, in run_feature_selection
    features_dropped = fs(default_hyperparameters)
                       ^^^^^^^^^^^^^^^^^^^^^^^^^^^
  File "c:\Users\prana\OneDrive\Desktop\Application\pipeline.py", line 15, in fs
    with mlflow.start_run() as run:
         ^^^^^^^^^^^^^^^^^^
  File "C:\Users\prana\AppData\Local\Programs\Python\Python312\Lib\site-packages\mlflow\tracking\fluent.py", line 351, in start_run
    raise Exception(
Exception: Run with UUID 643a82c13224408281a57325fc8e5998 is already active. To start a new run, first end the current run with mlflow.end_run(). To start a nested run, call start_run with nested=True

2025-04-24 18:36:17 - ERROR - Error in setup: Run with UUID 643a82c13224408281a57325fc8e5998 is already active. To start a new run, first end the current run with mlflow.end_run(). To start a nested run, call start_run with nested=True
2025-04-24 18:36:17 - ERROR - Traceback (most recent call last):
  File "c:\Users\prana\OneDrive\Desktop\Application\run_fs.py", line 35, in run_feature_selection
    features_dropped = fs(default_hyperparameters)
                       ^^^^^^^^^^^^^^^^^^^^^^^^^^^
  File "c:\Users\prana\OneDrive\Desktop\Application\pipeline.py", line 15, in fs
    with mlflow.start_run() as run:
         ^^^^^^^^^^^^^^^^^^
  File "C:\Users\prana\AppData\Local\Programs\Python\Python312\Lib\site-packages\mlflow\tracking\fluent.py", line 351, in start_run
    raise Exception(
Exception: Run with UUID 643a82c13224408281a57325fc8e5998 is already active. To start a new run, first end the current run with mlflow.end_run(). To start a nested run, call start_run with nested=True

2025-04-24 18:42:26 - INFO - Default parameters: {'train_file': 'input data/dev.csv', 'validation_file': 'input data/oos.csv', 'test_file': 'input data/oot.csv', 'target_column': 'Class', 'drop_features': 'no', 'train_on': 'normal', 'feature_selection': 'fpi', 'feature_threshold': 0.1, 'model_threshold': 0.5, 'model': 'LogisticRegression', 'cross_validation': 5, 'autoencoder': {'ratios': [0.8, 0.5, 0.2], 'epochs': 10, 'batch_size': 32, 'dropout': 0.1, 'hidden_activation': 'selu', 'optimizer': 'adam', 'loss': 'mse'}}
2025-04-24 18:42:29 - INFO - Running initial feature selection using default parameters
2025-04-24 18:45:15 - ERROR - Error during feature selection: [Errno 2] No such file or directory: 'input_data/dev.csv'
2025-04-24 18:45:15 - ERROR - Traceback (most recent call last):
  File "c:\Users\prana\OneDrive\Desktop\Application\run_fs.py", line 47, in run_feature_selection
    log_metrics_and_artifacts(
  File "c:\Users\prana\OneDrive\Desktop\Application\mlflow_utils.py", line 35, in log_metrics_and_artifacts
    mlflow.log_artifact("input_data/dev.csv", "datasets")
  File "C:\Users\prana\AppData\Local\Programs\Python\Python312\Lib\site-packages\mlflow\tracking\fluent.py", line 1179, in log_artifact
    MlflowClient().log_artifact(run_id, local_path, artifact_path)
  File "C:\Users\prana\AppData\Local\Programs\Python\Python312\Lib\site-packages\mlflow\tracking\client.py", line 2374, in log_artifact
    self._tracking_client.log_artifact(run_id, local_path, artifact_path)
  File "C:\Users\prana\AppData\Local\Programs\Python\Python312\Lib\site-packages\mlflow\tracking\_tracking_service\client.py", line 926, in log_artifact
    artifact_repo.log_artifact(local_path, artifact_path)
  File "C:\Users\prana\AppData\Local\Programs\Python\Python312\Lib\site-packages\mlflow\store\artifact\http_artifact_repo.py", line 62, in log_artifact
    with open(local_file, "rb") as f:
         ^^^^^^^^^^^^^^^^^^^^^^
FileNotFoundError: [Errno 2] No such file or directory: 'input_data/dev.csv'

2025-04-24 18:45:15 - ERROR - Error in setup: [Errno 2] No such file or directory: 'input_data/dev.csv'
2025-04-24 18:45:15 - ERROR - Traceback (most recent call last):
  File "c:\Users\prana\OneDrive\Desktop\Application\run_fs.py", line 47, in run_feature_selection
    log_metrics_and_artifacts(
  File "c:\Users\prana\OneDrive\Desktop\Application\mlflow_utils.py", line 35, in log_metrics_and_artifacts
    mlflow.log_artifact("input_data/dev.csv", "datasets")
  File "C:\Users\prana\AppData\Local\Programs\Python\Python312\Lib\site-packages\mlflow\tracking\fluent.py", line 1179, in log_artifact
    MlflowClient().log_artifact(run_id, local_path, artifact_path)
  File "C:\Users\prana\AppData\Local\Programs\Python\Python312\Lib\site-packages\mlflow\tracking\client.py", line 2374, in log_artifact
    self._tracking_client.log_artifact(run_id, local_path, artifact_path)
  File "C:\Users\prana\AppData\Local\Programs\Python\Python312\Lib\site-packages\mlflow\tracking\_tracking_service\client.py", line 926, in log_artifact
    artifact_repo.log_artifact(local_path, artifact_path)
  File "C:\Users\prana\AppData\Local\Programs\Python\Python312\Lib\site-packages\mlflow\store\artifact\http_artifact_repo.py", line 62, in log_artifact
    with open(local_file, "rb") as f:
         ^^^^^^^^^^^^^^^^^^^^^^
FileNotFoundError: [Errno 2] No such file or directory: 'input_data/dev.csv'

2025-04-24 18:48:57 - INFO - Default parameters: {'train_file': 'input data/dev.csv', 'validation_file': 'input data/oos.csv', 'test_file': 'input data/oot.csv', 'target_column': 'Class', 'drop_features': 'no', 'train_on': 'normal', 'feature_selection': 'fpi', 'feature_threshold': 0.1, 'model_threshold': 0.5, 'model': 'LogisticRegression', 'cross_validation': 5, 'autoencoder': {'ratios': [0.8, 0.5, 0.2], 'epochs': 10, 'batch_size': 32, 'dropout': 0.1, 'hidden_activation': 'selu', 'optimizer': 'adam', 'loss': 'mse'}}
2025-04-24 18:48:59 - INFO - Running initial feature selection using default parameters
2025-04-24 18:51:48 - ERROR - Error during feature selection: Cannot save file into a non-existent directory: 'feature_selection'
2025-04-24 18:51:48 - ERROR - Traceback (most recent call last):
  File "c:\Users\prana\OneDrive\Desktop\Application\run_fs.py", line 47, in run_feature_selection
    log_metrics_and_artifacts(
  File "c:\Users\prana\OneDrive\Desktop\Application\mlflow_utils.py", line 45, in log_metrics_and_artifacts
    dev_profile.to_csv("feature_selection/dev_profile.csv")
  File "C:\Users\prana\AppData\Local\Programs\Python\Python312\Lib\site-packages\pandas\core\generic.py", line 3902, in to_csv
    return DataFrameRenderer(formatter).to_csv(
           ^^^^^^^^^^^^^^^^^^^^^^^^^^^^^^^^^^^^
  File "C:\Users\prana\AppData\Local\Programs\Python\Python312\Lib\site-packages\pandas\io\formats\format.py", line 1152, in to_csv
    csv_formatter.save()
  File "C:\Users\prana\AppData\Local\Programs\Python\Python312\Lib\site-packages\pandas\io\formats\csvs.py", line 247, in save
    with get_handle(
         ^^^^^^^^^^^
  File "C:\Users\prana\AppData\Local\Programs\Python\Python312\Lib\site-packages\pandas\io\common.py", line 739, in get_handle
    check_parent_directory(str(handle))
  File "C:\Users\prana\AppData\Local\Programs\Python\Python312\Lib\site-packages\pandas\io\common.py", line 604, in check_parent_directory
    raise OSError(rf"Cannot save file into a non-existent directory: '{parent}'")
OSError: Cannot save file into a non-existent directory: 'feature_selection'

2025-04-24 18:51:48 - ERROR - Error in setup: Cannot save file into a non-existent directory: 'feature_selection'
2025-04-24 18:51:48 - ERROR - Traceback (most recent call last):
  File "c:\Users\prana\OneDrive\Desktop\Application\run_fs.py", line 47, in run_feature_selection
    log_metrics_and_artifacts(
  File "c:\Users\prana\OneDrive\Desktop\Application\mlflow_utils.py", line 45, in log_metrics_and_artifacts
    dev_profile.to_csv("feature_selection/dev_profile.csv")
  File "C:\Users\prana\AppData\Local\Programs\Python\Python312\Lib\site-packages\pandas\core\generic.py", line 3902, in to_csv
    return DataFrameRenderer(formatter).to_csv(
           ^^^^^^^^^^^^^^^^^^^^^^^^^^^^^^^^^^^^
  File "C:\Users\prana\AppData\Local\Programs\Python\Python312\Lib\site-packages\pandas\io\formats\format.py", line 1152, in to_csv
    csv_formatter.save()
  File "C:\Users\prana\AppData\Local\Programs\Python\Python312\Lib\site-packages\pandas\io\formats\csvs.py", line 247, in save
    with get_handle(
         ^^^^^^^^^^^
  File "C:\Users\prana\AppData\Local\Programs\Python\Python312\Lib\site-packages\pandas\io\common.py", line 739, in get_handle
    check_parent_directory(str(handle))
  File "C:\Users\prana\AppData\Local\Programs\Python\Python312\Lib\site-packages\pandas\io\common.py", line 604, in check_parent_directory
    raise OSError(rf"Cannot save file into a non-existent directory: '{parent}'")
OSError: Cannot save file into a non-existent directory: 'feature_selection'

2025-04-24 18:53:29 - INFO - Default parameters: {'train_file': 'input data/dev.csv', 'validation_file': 'input data/oos.csv', 'test_file': 'input data/oot.csv', 'target_column': 'Class', 'drop_features': 'no', 'train_on': 'normal', 'feature_selection': 'fpi', 'feature_threshold': 0.1, 'model_threshold': 0.5, 'model': 'LogisticRegression', 'cross_validation': 5, 'autoencoder': {'ratios': [0.8, 0.5, 0.2], 'epochs': 10, 'batch_size': 32, 'dropout': 0.1, 'hidden_activation': 'selu', 'optimizer': 'adam', 'loss': 'mse'}}
2025-04-24 18:53:31 - INFO - Running initial feature selection using default parameters
2025-04-24 18:56:39 - INFO - Feature selection completed. Dropped features: ['V2', 'V8', 'V9', 'V11', 'V19', 'V20']
2025-04-24 19:02:19 - INFO - Default parameters: {'train_file': 'input data/dev.csv', 'validation_file': 'input data/oos.csv', 'test_file': 'input data/oot.csv', 'target_column': 'Class', 'drop_features': 'no', 'train_on': 'normal', 'feature_selection': 'fpi', 'feature_threshold': 0.1, 'model_threshold': 0.5, 'model': 'LogisticRegression', 'cross_validation': 5, 'autoencoder': {'ratios': [0.8, 0.5, 0.2], 'epochs': 10, 'batch_size': 32, 'dropout': 0.1, 'hidden_activation': 'selu', 'optimizer': 'adam', 'loss': 'mse'}}
2025-04-24 19:02:22 - INFO - Running initial feature selection using default parameters
2025-04-24 19:05:26 - ERROR - Error during feature selection: [Errno 2] No such file or directory: 'input_data/dev.csv'
2025-04-24 19:05:26 - ERROR - Traceback (most recent call last):
  File "c:\Users\prana\OneDrive\Desktop\Application\run_fs.py", line 47, in run_feature_selection
    log_metrics_and_artifacts(
  File "c:\Users\prana\OneDrive\Desktop\Application\mlflow_utils.py", line 35, in log_metrics_and_artifacts
    mlflow.log_artifact("input_data/dev.csv", "datasets")
  File "C:\Users\prana\AppData\Local\Programs\Python\Python312\Lib\site-packages\mlflow\tracking\fluent.py", line 1179, in log_artifact
    MlflowClient().log_artifact(run_id, local_path, artifact_path)
  File "C:\Users\prana\AppData\Local\Programs\Python\Python312\Lib\site-packages\mlflow\tracking\client.py", line 2374, in log_artifact
    self._tracking_client.log_artifact(run_id, local_path, artifact_path)
  File "C:\Users\prana\AppData\Local\Programs\Python\Python312\Lib\site-packages\mlflow\tracking\_tracking_service\client.py", line 926, in log_artifact
    artifact_repo.log_artifact(local_path, artifact_path)
  File "C:\Users\prana\AppData\Local\Programs\Python\Python312\Lib\site-packages\mlflow\store\artifact\http_artifact_repo.py", line 62, in log_artifact
    with open(local_file, "rb") as f:
         ^^^^^^^^^^^^^^^^^^^^^^
FileNotFoundError: [Errno 2] No such file or directory: 'input_data/dev.csv'

2025-04-24 19:05:26 - ERROR - Error in setup: [Errno 2] No such file or directory: 'input_data/dev.csv'
2025-04-24 19:05:26 - ERROR - Traceback (most recent call last):
  File "c:\Users\prana\OneDrive\Desktop\Application\run_fs.py", line 47, in run_feature_selection
    log_metrics_and_artifacts(
  File "c:\Users\prana\OneDrive\Desktop\Application\mlflow_utils.py", line 35, in log_metrics_and_artifacts
    mlflow.log_artifact("input_data/dev.csv", "datasets")
  File "C:\Users\prana\AppData\Local\Programs\Python\Python312\Lib\site-packages\mlflow\tracking\fluent.py", line 1179, in log_artifact
    MlflowClient().log_artifact(run_id, local_path, artifact_path)
  File "C:\Users\prana\AppData\Local\Programs\Python\Python312\Lib\site-packages\mlflow\tracking\client.py", line 2374, in log_artifact
    self._tracking_client.log_artifact(run_id, local_path, artifact_path)
  File "C:\Users\prana\AppData\Local\Programs\Python\Python312\Lib\site-packages\mlflow\tracking\_tracking_service\client.py", line 926, in log_artifact
    artifact_repo.log_artifact(local_path, artifact_path)
  File "C:\Users\prana\AppData\Local\Programs\Python\Python312\Lib\site-packages\mlflow\store\artifact\http_artifact_repo.py", line 62, in log_artifact
    with open(local_file, "rb") as f:
         ^^^^^^^^^^^^^^^^^^^^^^
FileNotFoundError: [Errno 2] No such file or directory: 'input_data/dev.csv'

2025-04-24 19:07:11 - INFO - Default parameters: {'train_file': 'input data/dev.csv', 'validation_file': 'input data/oos.csv', 'test_file': 'input data/oot.csv', 'target_column': 'Class', 'drop_features': 'no', 'train_on': 'normal', 'feature_selection': 'fpi', 'feature_threshold': 0.1, 'model_threshold': 0.5, 'model': 'LogisticRegression', 'cross_validation': 5, 'autoencoder': {'ratios': [0.8, 0.5, 0.2], 'epochs': 10, 'batch_size': 32, 'dropout': 0.1, 'hidden_activation': 'selu', 'optimizer': 'adam', 'loss': 'mse'}}
2025-04-24 19:07:13 - INFO - Running initial feature selection using default parameters
2025-04-24 19:10:05 - INFO - Feature selection completed. Dropped features: ['V4', 'V6', 'V9', 'V11', 'V12', 'V20', 'V25']
2025-04-24 19:11:55 - INFO - Default parameters: {'train_file': 'input data/dev.csv', 'validation_file': 'input data/oos.csv', 'test_file': 'input data/oot.csv', 'target_column': 'Class', 'drop_features': 'no', 'train_on': 'normal', 'feature_selection': 'fpi', 'feature_threshold': 0.1, 'model_threshold': 0.5, 'model': 'LogisticRegression', 'cross_validation': 5, 'autoencoder': {'ratios': [0.8, 0.5, 0.2], 'epochs': 10, 'batch_size': 32, 'dropout': 0.1, 'hidden_activation': 'selu', 'optimizer': 'adam', 'loss': 'mse'}}
2025-04-24 19:11:57 - INFO - Running initial feature selection using default parameters
2025-04-24 19:14:59 - INFO - Feature selection completed. Dropped features: ['V4', 'V11', 'V12', 'V15', 'V24', 'V25', 'V26']
2025-04-24 19:34:18 - INFO - Default parameters: {'train_file': 'input data/dev.csv', 'validation_file': 'input data/oos.csv', 'test_file': 'input data/oot.csv', 'target_column': 'Class', 'drop_features': 'no', 'train_on': 'normal', 'feature_selection': 'fpi', 'feature_threshold': 0.1, 'model_threshold': 0.5, 'model': 'LogisticRegression', 'cross_validation': 5, 'autoencoder': {'ratios': [0.8, 0.5, 0.2], 'epochs': 10, 'batch_size': 32, 'dropout': 0.1, 'hidden_activation': 'selu', 'optimizer': 'adam', 'loss': 'mse'}}
2025-04-24 19:34:20 - INFO - Running initial feature selection using default parameters
2025-04-24 19:37:24 - INFO - Feature selection completed. Dropped features: ['V1', 'V4', 'V10', 'V12', 'V14', 'V18', 'V24', 'V28']
2025-04-24 19:42:14 - INFO - Default parameters: {'train_file': 'input data/dev.csv', 'validation_file': 'input data/oos.csv', 'test_file': 'input data/oot.csv', 'target_column': 'Class', 'drop_features': 'no', 'train_on': 'normal', 'feature_selection': 'fpi', 'feature_threshold': 0.1, 'model_threshold': 0.5, 'model': 'LogisticRegression', 'cross_validation': 5, 'autoencoder': {'ratios': [0.8, 0.5, 0.2], 'epochs': 10, 'batch_size': 32, 'dropout': 0.1, 'hidden_activation': 'selu', 'optimizer': 'adam', 'loss': 'mse'}}
2025-04-24 19:42:17 - INFO - Running initial feature selection using default parameters
2025-04-24 19:45:06 - INFO - Feature selection completed. Dropped features: ['V1', 'V4', 'V7', 'V9', 'V11', 'V18', 'V20', 'V22', 'V26', 'V27']
2025-04-24 19:47:32 - INFO - Default parameters: {'train_file': 'input data/dev.csv', 'validation_file': 'input data/oos.csv', 'test_file': 'input data/oot.csv', 'target_column': 'Class', 'drop_features': 'no', 'train_on': 'normal', 'feature_selection': 'fpi', 'feature_threshold': 0.1, 'model_threshold': 0.5, 'model': 'LogisticRegression', 'cross_validation': 5, 'autoencoder': {'ratios': [0.8, 0.5, 0.2], 'epochs': 10, 'batch_size': 32, 'dropout': 0.1, 'hidden_activation': 'selu', 'optimizer': 'adam', 'loss': 'mse'}}
2025-04-24 19:47:34 - INFO - Running initial feature selection using default parameters
2025-04-24 19:50:46 - INFO - Feature selection completed. Dropped features: ['V1', 'V3', 'V4', 'V6', 'V8', 'V9', 'V18', 'V20', 'V22', 'V25', 'V26', 'V27', 'Amount']
2025-04-24 19:57:52 - INFO - Default parameters: {'train_file': 'input data/dev.csv', 'validation_file': 'input data/oos.csv', 'test_file': 'input data/oot.csv', 'target_column': 'Class', 'drop_features': 'no', 'train_on': 'normal', 'feature_selection': 're', 'feature_threshold': 0.1, 'model_threshold': 0.5, 'model': 'LogisticRegression', 'cross_validation': 5, 'autoencoder': {'ratios': [0.8, 0.5, 0.2], 'epochs': 10, 'batch_size': 32, 'dropout': 0.1, 'hidden_activation': 'selu', 'optimizer': 'adam', 'loss': 'mse'}}
2025-04-24 19:57:55 - INFO - Running initial feature selection using default parameters
2025-04-24 19:59:06 - ERROR - Error during feature selection: [Errno 2] No such file or directory: "'feature selection/abnormal_'+re+'_importance.csv'"
2025-04-24 19:59:06 - ERROR - Traceback (most recent call last):
  File "c:\Users\prana\OneDrive\Desktop\Application\run_fs.py", line 46, in run_feature_selection
    log_metrics_and_artifacts(
  File "c:\Users\prana\OneDrive\Desktop\Application\mlflow_utils.py", line 40, in log_metrics_and_artifacts
    mlflow.log_artifact(f"'feature selection/abnormal_'+{method}+'_importance.csv'", "feature_importance")
  File "C:\Users\prana\AppData\Local\Programs\Python\Python312\Lib\site-packages\mlflow\tracking\fluent.py", line 1179, in log_artifact
    MlflowClient().log_artifact(run_id, local_path, artifact_path)
  File "C:\Users\prana\AppData\Local\Programs\Python\Python312\Lib\site-packages\mlflow\tracking\client.py", line 2374, in log_artifact
    self._tracking_client.log_artifact(run_id, local_path, artifact_path)
  File "C:\Users\prana\AppData\Local\Programs\Python\Python312\Lib\site-packages\mlflow\tracking\_tracking_service\client.py", line 926, in log_artifact
    artifact_repo.log_artifact(local_path, artifact_path)
  File "C:\Users\prana\AppData\Local\Programs\Python\Python312\Lib\site-packages\mlflow\store\artifact\http_artifact_repo.py", line 62, in log_artifact
    with open(local_file, "rb") as f:
         ^^^^^^^^^^^^^^^^^^^^^^
FileNotFoundError: [Errno 2] No such file or directory: "'feature selection/abnormal_'+re+'_importance.csv'"

2025-04-24 19:59:06 - ERROR - Error in setup: [Errno 2] No such file or directory: "'feature selection/abnormal_'+re+'_importance.csv'"
2025-04-24 19:59:06 - ERROR - Traceback (most recent call last):
  File "c:\Users\prana\OneDrive\Desktop\Application\run_fs.py", line 46, in run_feature_selection
    log_metrics_and_artifacts(
  File "c:\Users\prana\OneDrive\Desktop\Application\mlflow_utils.py", line 40, in log_metrics_and_artifacts
    mlflow.log_artifact(f"'feature selection/abnormal_'+{method}+'_importance.csv'", "feature_importance")
  File "C:\Users\prana\AppData\Local\Programs\Python\Python312\Lib\site-packages\mlflow\tracking\fluent.py", line 1179, in log_artifact
    MlflowClient().log_artifact(run_id, local_path, artifact_path)
  File "C:\Users\prana\AppData\Local\Programs\Python\Python312\Lib\site-packages\mlflow\tracking\client.py", line 2374, in log_artifact
    self._tracking_client.log_artifact(run_id, local_path, artifact_path)
  File "C:\Users\prana\AppData\Local\Programs\Python\Python312\Lib\site-packages\mlflow\tracking\_tracking_service\client.py", line 926, in log_artifact
    artifact_repo.log_artifact(local_path, artifact_path)
  File "C:\Users\prana\AppData\Local\Programs\Python\Python312\Lib\site-packages\mlflow\store\artifact\http_artifact_repo.py", line 62, in log_artifact
    with open(local_file, "rb") as f:
         ^^^^^^^^^^^^^^^^^^^^^^
FileNotFoundError: [Errno 2] No such file or directory: "'feature selection/abnormal_'+re+'_importance.csv'"

2025-04-24 20:04:12 - INFO - Default parameters: {'train_file': 'input data/dev.csv', 'validation_file': 'input data/oos.csv', 'test_file': 'input data/oot.csv', 'target_column': 'Class', 'drop_features': 'no', 'train_on': 'normal', 'feature_selection': 're', 'feature_threshold': 0.1, 'model_threshold': 0.5, 'model': 'LogisticRegression', 'cross_validation': 5, 'autoencoder': {'ratios': [0.8, 0.5, 0.2], 'epochs': 10, 'batch_size': 32, 'dropout': 0.1, 'hidden_activation': 'selu', 'optimizer': 'adam', 'loss': 'mse'}}
2025-04-24 20:04:14 - INFO - Running initial feature selection using default parameters
2025-04-24 20:05:28 - ERROR - Error during feature selection: can only concatenate str (not "set") to str
2025-04-24 20:05:28 - ERROR - Traceback (most recent call last):
  File "c:\Users\prana\OneDrive\Desktop\Application\run_fs.py", line 46, in run_feature_selection
    log_metrics_and_artifacts(
  File "c:\Users\prana\OneDrive\Desktop\Application\mlflow_utils.py", line 40, in log_metrics_and_artifacts
    mlflow.log_artifact('feature selection/abnormal_'+{method}+'_importance.csv', "feature_importance")
                        ~~~~~~~~~~~~~~~~~~~~~~~~~~~~~^~~~~~~~~
TypeError: can only concatenate str (not "set") to str

2025-04-24 20:05:28 - ERROR - Error in setup: can only concatenate str (not "set") to str
2025-04-24 20:05:28 - ERROR - Traceback (most recent call last):
  File "c:\Users\prana\OneDrive\Desktop\Application\run_fs.py", line 46, in run_feature_selection
    log_metrics_and_artifacts(
  File "c:\Users\prana\OneDrive\Desktop\Application\mlflow_utils.py", line 40, in log_metrics_and_artifacts
    mlflow.log_artifact('feature selection/abnormal_'+{method}+'_importance.csv', "feature_importance")
                        ~~~~~~~~~~~~~~~~~~~~~~~~~~~~~^~~~~~~~~
TypeError: can only concatenate str (not "set") to str

2025-04-24 20:07:37 - INFO - Default parameters: {'train_file': 'input data/dev.csv', 'validation_file': 'input data/oos.csv', 'test_file': 'input data/oot.csv', 'target_column': 'Class', 'drop_features': 'no', 'train_on': 'normal', 'feature_selection': 're', 'feature_threshold': 0.1, 'model_threshold': 0.5, 'model': 'LogisticRegression', 'cross_validation': 5, 'autoencoder': {'ratios': [0.8, 0.5, 0.2], 'epochs': 10, 'batch_size': 32, 'dropout': 0.1, 'hidden_activation': 'selu', 'optimizer': 'adam', 'loss': 'mse'}}
2025-04-24 20:07:40 - INFO - Running initial feature selection using default parameters
2025-04-24 20:08:55 - INFO - Feature selection completed. Dropped features: ['V27', 'V28']
2025-04-24 20:12:10 - INFO - Default parameters: {'train_file': 'input data/dev.csv', 'validation_file': 'input data/oos.csv', 'test_file': 'input data/oot.csv', 'target_column': 'Class', 'drop_features': 'no', 'train_on': 'normal', 'feature_selection': 're', 'feature_threshold': 0.1, 'model_threshold': 0.5, 'model': 'LogisticRegression', 'cross_validation': 5, 'autoencoder': {'ratios': [0.8, 0.5, 0.2], 'epochs': 10, 'batch_size': 32, 'dropout': 0.1, 'hidden_activation': 'selu', 'optimizer': 'adam', 'loss': 'mse'}}
2025-04-24 20:12:13 - INFO - Running initial feature selection using default parameters
2025-04-24 20:13:22 - INFO - Feature selection completed. Dropped features: ['V23', 'V28']
2025-04-24 20:24:36 - INFO - Default parameters: {'train_file': 'input data/dev.csv', 'validation_file': 'input data/oos.csv', 'test_file': 'input data/oot.csv', 'target_column': 'Class', 'drop_features': 'no', 'train_on': 'normal', 'feature_selection': 're', 'feature_threshold': 0.1, 'model_threshold': 0.5, 'model': 'LogisticRegression', 'cross_validation': 5, 'autoencoder': {'ratios': [0.8, 0.5, 0.2], 'epochs': 10, 'batch_size': 32, 'dropout': 0.1, 'hidden_activation': 'selu', 'optimizer': 'adam', 'loss': 'mse'}}
2025-04-24 20:24:38 - INFO - Running initial feature selection using default parameters
2025-04-24 20:25:45 - INFO - Feature selection completed. Dropped features: ['V23', 'V28']
2025-04-24 20:33:21 - INFO - Default parameters: {'train_file': 'input data/dev.csv', 'validation_file': 'input data/oos.csv', 'test_file': 'input data/oot.csv', 'target_column': 'Class', 'drop_features': 'no', 'train_on': 'normal', 'feature_selection': 're', 'feature_threshold': 0.1, 'model_threshold': 0.5, 'model': 'LogisticRegression', 'cross_validation': 5, 'autoencoder': {'ratios': [0.8, 0.5, 0.2], 'epochs': 10, 'batch_size': 32, 'dropout': 0.1, 'hidden_activation': 'selu', 'optimizer': 'adam', 'loss': 'mse'}}
2025-04-24 20:33:24 - INFO - Running initial feature selection using default parameters
2025-04-24 20:34:37 - ERROR - Error during feature selection: [Errno 2] No such file or directory: 'figures/normal_fpi_importance.png'
2025-04-24 20:34:37 - ERROR - Traceback (most recent call last):
  File "c:\Users\prana\OneDrive\Desktop\Application\run_fs.py", line 46, in run_feature_selection
    log_metrics_and_artifacts(
  File "c:\Users\prana\OneDrive\Desktop\Application\mlflow_utils.py", line 109, in log_metrics_and_artifacts
    mlflow.log_artifact(fig_path)
  File "C:\Users\prana\AppData\Local\Programs\Python\Python312\Lib\site-packages\mlflow\tracking\fluent.py", line 1179, in log_artifact
    MlflowClient().log_artifact(run_id, local_path, artifact_path)
  File "C:\Users\prana\AppData\Local\Programs\Python\Python312\Lib\site-packages\mlflow\tracking\client.py", line 2374, in log_artifact
    self._tracking_client.log_artifact(run_id, local_path, artifact_path)
  File "C:\Users\prana\AppData\Local\Programs\Python\Python312\Lib\site-packages\mlflow\tracking\_tracking_service\client.py", line 926, in log_artifact
    artifact_repo.log_artifact(local_path, artifact_path)
  File "C:\Users\prana\AppData\Local\Programs\Python\Python312\Lib\site-packages\mlflow\store\artifact\http_artifact_repo.py", line 62, in log_artifact
    with open(local_file, "rb") as f:
         ^^^^^^^^^^^^^^^^^^^^^^
FileNotFoundError: [Errno 2] No such file or directory: 'figures/normal_fpi_importance.png'

2025-04-24 20:34:37 - ERROR - Error in setup: [Errno 2] No such file or directory: 'figures/normal_fpi_importance.png'
2025-04-24 20:34:37 - ERROR - Traceback (most recent call last):
  File "c:\Users\prana\OneDrive\Desktop\Application\run_fs.py", line 46, in run_feature_selection
    log_metrics_and_artifacts(
  File "c:\Users\prana\OneDrive\Desktop\Application\mlflow_utils.py", line 109, in log_metrics_and_artifacts
    mlflow.log_artifact(fig_path)
  File "C:\Users\prana\AppData\Local\Programs\Python\Python312\Lib\site-packages\mlflow\tracking\fluent.py", line 1179, in log_artifact
    MlflowClient().log_artifact(run_id, local_path, artifact_path)
  File "C:\Users\prana\AppData\Local\Programs\Python\Python312\Lib\site-packages\mlflow\tracking\client.py", line 2374, in log_artifact
    self._tracking_client.log_artifact(run_id, local_path, artifact_path)
  File "C:\Users\prana\AppData\Local\Programs\Python\Python312\Lib\site-packages\mlflow\tracking\_tracking_service\client.py", line 926, in log_artifact
    artifact_repo.log_artifact(local_path, artifact_path)
  File "C:\Users\prana\AppData\Local\Programs\Python\Python312\Lib\site-packages\mlflow\store\artifact\http_artifact_repo.py", line 62, in log_artifact
    with open(local_file, "rb") as f:
         ^^^^^^^^^^^^^^^^^^^^^^
FileNotFoundError: [Errno 2] No such file or directory: 'figures/normal_fpi_importance.png'

2025-04-24 20:39:10 - INFO - Default parameters: {'train_file': 'input data/dev.csv', 'validation_file': 'input data/oos.csv', 'test_file': 'input data/oot.csv', 'target_column': 'Class', 'drop_features': 'no', 'train_on': 'normal', 'feature_selection': 're', 'feature_threshold': 0.1, 'model_threshold': 0.5, 'model': 'LogisticRegression', 'cross_validation': 5, 'autoencoder': {'ratios': [0.8, 0.5, 0.2], 'epochs': 10, 'batch_size': 32, 'dropout': 0.1, 'hidden_activation': 'selu', 'optimizer': 'adam', 'loss': 'mse'}}
2025-04-24 20:39:13 - INFO - Running initial feature selection using default parameters
2025-04-24 20:40:25 - INFO - Feature selection completed. Dropped features: ['V27', 'V28']
2025-04-24 20:42:51 - INFO - Default parameters: {'train_file': 'input data/dev.csv', 'validation_file': 'input data/oos.csv', 'test_file': 'input data/oot.csv', 'target_column': 'Class', 'drop_features': 'no', 'train_on': 'normal', 'feature_selection': 'fpi', 'feature_threshold': 0.1, 'model_threshold': 0.5, 'model': 'LogisticRegression', 'cross_validation': 5, 'autoencoder': {'ratios': [0.8, 0.5, 0.2], 'epochs': 10, 'batch_size': 32, 'dropout': 0.1, 'hidden_activation': 'selu', 'optimizer': 'adam', 'loss': 'mse'}}
2025-04-24 20:42:54 - INFO - Running initial feature selection using default parameters
2025-04-24 20:45:55 - INFO - Feature selection completed. Dropped features: ['V1', 'V2', 'V3', 'V9', 'V11', 'V12', 'V13', 'V14', 'V16', 'V17', 'V18', 'V20', 'V26']
2025-04-25 16:25:55 - INFO - Default parameters: {'train_file': 'input data/dev.csv', 'validation_file': 'input data/oos.csv', 'test_file': 'input data/oot.csv', 'target_column': 'Class', 'drop_features': 'no', 'train_on': 'normal', 'feature_selection': 'fpi', 'feature_threshold': 0.1, 'model_threshold': 0.5, 'model': 'LogisticRegression', 'cross_validation': 5, 'autoencoder': {'ratios': [0.8, 0.5, 0.2], 'epochs': 10, 'batch_size': 32, 'dropout': 0.1, 'hidden_activation': 'selu', 'optimizer': 'adam', 'loss': 'mse'}}
2025-04-25 16:25:57 - INFO - Running initial feature selection using default parameters
2025-04-25 16:29:00 - INFO - Feature selection completed. Dropped features: ['V1', 'V2', 'V4', 'V5', 'V9', 'V20', 'V22', 'V26']
2025-04-27 16:59:58 - INFO - Default parameters: {'train_file': 'input data/dev.csv', 'validation_file': 'input data/oos.csv', 'test_file': 'input data/oot.csv', 'target_column': 'Class', 'train_on': 'normal', 'feature_selection': 'fpi', 'feature_threshold': 0.1, 'model_threshold': 0, 'model': 'LogisticRegression', 'cross_validation': 5, 'autoencoder': {'ratios': [0.8, 0.5, 0.2], 'epochs': 10, 'batch_size': 32, 'dropout': 0.1, 'hidden_activation': 'selu', 'optimizer': 'adam', 'loss': 'mse'}, 'model_params': {'C': 0.01, 'penalty': 'l2', 'solver': 'lbfgs', 'max_iter': 200, 'random_state': 42}}
2025-04-27 17:00:02 - WARNING - Retrying (Retry(total=6, connect=6, read=7, redirect=7, status=7)) after connection broken by 'NewConnectionError('<urllib3.connection.HTTPConnection object at 0x000002448E3407A0>: Failed to establish a new connection: [WinError 10061] No connection could be made because the target machine actively refused it')': /api/2.0/mlflow/experiments/get-by-name?experiment_name=Feature_Selection_Pipeline
2025-04-27 17:00:11 - WARNING - Retrying (Retry(total=5, connect=5, read=7, redirect=7, status=7)) after connection broken by 'NewConnectionError('<urllib3.connection.HTTPConnection object at 0x000002448E340B60>: Failed to establish a new connection: [WinError 10061] No connection could be made because the target machine actively refused it')': /api/2.0/mlflow/experiments/get-by-name?experiment_name=Feature_Selection_Pipeline
2025-04-27 17:00:23 - WARNING - Retrying (Retry(total=4, connect=4, read=7, redirect=7, status=7)) after connection broken by 'NewConnectionError('<urllib3.connection.HTTPConnection object at 0x000002448E340950>: Failed to establish a new connection: [WinError 10061] No connection could be made because the target machine actively refused it')': /api/2.0/mlflow/experiments/get-by-name?experiment_name=Feature_Selection_Pipeline
2025-04-27 17:00:44 - WARNING - Retrying (Retry(total=3, connect=3, read=7, redirect=7, status=7)) after connection broken by 'NewConnectionError('<urllib3.connection.HTTPConnection object at 0x000002448E341190>: Failed to establish a new connection: [WinError 10061] No connection could be made because the target machine actively refused it')': /api/2.0/mlflow/experiments/get-by-name?experiment_name=Feature_Selection_Pipeline
2025-04-27 17:01:21 - WARNING - Retrying (Retry(total=2, connect=2, read=7, redirect=7, status=7)) after connection broken by 'NewConnectionError('<urllib3.connection.HTTPConnection object at 0x000002448E3413D0>: Failed to establish a new connection: [WinError 10061] No connection could be made because the target machine actively refused it')': /api/2.0/mlflow/experiments/get-by-name?experiment_name=Feature_Selection_Pipeline
2025-04-27 17:02:29 - INFO - Default parameters: {'train_file': 'input data/dev.csv', 'validation_file': 'input data/oos.csv', 'test_file': 'input data/oot.csv', 'target_column': 'Class', 'train_on': 'normal', 'feature_selection': 'fpi', 'feature_threshold': 0.1, 'model_threshold': 0, 'model': 'LogisticRegression', 'cross_validation': 5, 'autoencoder': {'ratios': [0.8, 0.5, 0.2], 'epochs': 10, 'batch_size': 32, 'dropout': 0.1, 'hidden_activation': 'selu', 'optimizer': 'adam', 'loss': 'mse'}, 'model_params': {'C': 0.01, 'penalty': 'l2', 'solver': 'lbfgs', 'max_iter': 200, 'random_state': 42}}
2025-04-27 17:02:33 - WARNING - Retrying (Retry(total=6, connect=6, read=7, redirect=7, status=7)) after connection broken by 'NewConnectionError('<urllib3.connection.HTTPConnection object at 0x000001BA565A20C0>: Failed to establish a new connection: [WinError 10061] No connection could be made because the target machine actively refused it')': /api/2.0/mlflow/experiments/get-by-name?experiment_name=Feature_Selection_Pipeline
2025-04-27 17:02:42 - WARNING - Retrying (Retry(total=5, connect=5, read=7, redirect=7, status=7)) after connection broken by 'NewConnectionError('<urllib3.connection.HTTPConnection object at 0x000001BA58590B30>: Failed to establish a new connection: [WinError 10061] No connection could be made because the target machine actively refused it')': /api/2.0/mlflow/experiments/get-by-name?experiment_name=Feature_Selection_Pipeline
2025-04-27 17:02:54 - WARNING - Retrying (Retry(total=4, connect=4, read=7, redirect=7, status=7)) after connection broken by 'NewConnectionError('<urllib3.connection.HTTPConnection object at 0x000001BA58590920>: Failed to establish a new connection: [WinError 10061] No connection could be made because the target machine actively refused it')': /api/2.0/mlflow/experiments/get-by-name?experiment_name=Feature_Selection_Pipeline
2025-04-27 17:03:15 - WARNING - Retrying (Retry(total=3, connect=3, read=7, redirect=7, status=7)) after connection broken by 'NewConnectionError('<urllib3.connection.HTTPConnection object at 0x000001BA58591160>: Failed to establish a new connection: [WinError 10061] No connection could be made because the target machine actively refused it')': /api/2.0/mlflow/experiments/get-by-name?experiment_name=Feature_Selection_Pipeline
2025-04-27 17:03:52 - WARNING - Retrying (Retry(total=2, connect=2, read=7, redirect=7, status=7)) after connection broken by 'NewConnectionError('<urllib3.connection.HTTPConnection object at 0x000001BA585913A0>: Failed to establish a new connection: [WinError 10061] No connection could be made because the target machine actively refused it')': /api/2.0/mlflow/experiments/get-by-name?experiment_name=Feature_Selection_Pipeline
2025-04-27 17:05:01 - WARNING - Retrying (Retry(total=1, connect=1, read=7, redirect=7, status=7)) after connection broken by 'NewConnectionError('<urllib3.connection.HTTPConnection object at 0x000001BA58591550>: Failed to establish a new connection: [WinError 10061] No connection could be made because the target machine actively refused it')': /api/2.0/mlflow/experiments/get-by-name?experiment_name=Feature_Selection_Pipeline
2025-04-27 17:07:05 - WARNING - Retrying (Retry(total=0, connect=0, read=7, redirect=7, status=7)) after connection broken by 'NewConnectionError('<urllib3.connection.HTTPConnection object at 0x000001BA58591730>: Failed to establish a new connection: [WinError 10061] No connection could be made because the target machine actively refused it')': /api/2.0/mlflow/experiments/get-by-name?experiment_name=Feature_Selection_Pipeline
2025-04-27 17:07:09 - ERROR - Error in setup: API request to http://localhost:5000/api/2.0/mlflow/experiments/get-by-name failed with exception HTTPConnectionPool(host='localhost', port=5000): Max retries exceeded with url: /api/2.0/mlflow/experiments/get-by-name?experiment_name=Feature_Selection_Pipeline (Caused by NewConnectionError('<urllib3.connection.HTTPConnection object at 0x000001BA58591910>: Failed to establish a new connection: [WinError 10061] No connection could be made because the target machine actively refused it'))
2025-04-27 17:07:09 - ERROR - Traceback (most recent call last):
  File "C:\Users\prana\AppData\Local\Programs\Python\Python312\Lib\site-packages\urllib3\connection.py", line 203, in _new_conn
    sock = connection.create_connection(
           ^^^^^^^^^^^^^^^^^^^^^^^^^^^^^
  File "C:\Users\prana\AppData\Local\Programs\Python\Python312\Lib\site-packages\urllib3\util\connection.py", line 85, in create_connection
    raise err
  File "C:\Users\prana\AppData\Local\Programs\Python\Python312\Lib\site-packages\urllib3\util\connection.py", line 73, in create_connection
    sock.connect(sa)
ConnectionRefusedError: [WinError 10061] No connection could be made because the target machine actively refused it

The above exception was the direct cause of the following exception:

Traceback (most recent call last):
  File "C:\Users\prana\AppData\Local\Programs\Python\Python312\Lib\site-packages\urllib3\connectionpool.py", line 790, in urlopen
    response = self._make_request(
               ^^^^^^^^^^^^^^^^^^^
  File "C:\Users\prana\AppData\Local\Programs\Python\Python312\Lib\site-packages\urllib3\connectionpool.py", line 496, in _make_request
    conn.request(
  File "C:\Users\prana\AppData\Local\Programs\Python\Python312\Lib\site-packages\urllib3\connection.py", line 395, in request
    self.endheaders()
  File "C:\Users\prana\AppData\Local\Programs\Python\Python312\Lib\http\client.py", line 1322, in endheaders
    self._send_output(message_body, encode_chunked=encode_chunked)
  File "C:\Users\prana\AppData\Local\Programs\Python\Python312\Lib\http\client.py", line 1081, in _send_output
    self.send(msg)
  File "C:\Users\prana\AppData\Local\Programs\Python\Python312\Lib\http\client.py", line 1025, in send
    self.connect()
  File "C:\Users\prana\AppData\Local\Programs\Python\Python312\Lib\site-packages\urllib3\connection.py", line 243, in connect
    self.sock = self._new_conn()
                ^^^^^^^^^^^^^^^^
  File "C:\Users\prana\AppData\Local\Programs\Python\Python312\Lib\site-packages\urllib3\connection.py", line 218, in _new_conn
    raise NewConnectionError(
urllib3.exceptions.NewConnectionError: <urllib3.connection.HTTPConnection object at 0x000001BA58591910>: Failed to establish a new connection: [WinError 10061] No connection could be made because the target machine actively refused it

The above exception was the direct cause of the following exception:

Traceback (most recent call last):
  File "C:\Users\prana\AppData\Local\Programs\Python\Python312\Lib\site-packages\requests\adapters.py", line 667, in send
    resp = conn.urlopen(
           ^^^^^^^^^^^^^
  File "C:\Users\prana\AppData\Local\Programs\Python\Python312\Lib\site-packages\urllib3\connectionpool.py", line 874, in urlopen
    return self.urlopen(
           ^^^^^^^^^^^^^
  File "C:\Users\prana\AppData\Local\Programs\Python\Python312\Lib\site-packages\urllib3\connectionpool.py", line 874, in urlopen
    return self.urlopen(
           ^^^^^^^^^^^^^
  File "C:\Users\prana\AppData\Local\Programs\Python\Python312\Lib\site-packages\urllib3\connectionpool.py", line 874, in urlopen
    return self.urlopen(
           ^^^^^^^^^^^^^
  [Previous line repeated 4 more times]
  File "C:\Users\prana\AppData\Local\Programs\Python\Python312\Lib\site-packages\urllib3\connectionpool.py", line 844, in urlopen
    retries = retries.increment(
              ^^^^^^^^^^^^^^^^^^
  File "C:\Users\prana\AppData\Local\Programs\Python\Python312\Lib\site-packages\urllib3\util\retry.py", line 515, in increment
    raise MaxRetryError(_pool, url, reason) from reason  # type: ignore[arg-type]
    ^^^^^^^^^^^^^^^^^^^^^^^^^^^^^^^^^^^^^^^^^^^^^^^^^^^
urllib3.exceptions.MaxRetryError: HTTPConnectionPool(host='localhost', port=5000): Max retries exceeded with url: /api/2.0/mlflow/experiments/get-by-name?experiment_name=Feature_Selection_Pipeline (Caused by NewConnectionError('<urllib3.connection.HTTPConnection object at 0x000001BA58591910>: Failed to establish a new connection: [WinError 10061] No connection could be made because the target machine actively refused it'))

During handling of the above exception, another exception occurred:

Traceback (most recent call last):
  File "C:\Users\prana\AppData\Local\Programs\Python\Python312\Lib\site-packages\mlflow\utils\rest_utils.py", line 181, in http_request
    return _get_http_response_with_retries(
           ^^^^^^^^^^^^^^^^^^^^^^^^^^^^^^^^
  File "C:\Users\prana\AppData\Local\Programs\Python\Python312\Lib\site-packages\mlflow\utils\request_utils.py", line 237, in _get_http_response_with_retries
    return session.request(method, url, allow_redirects=allow_redirects, **kwargs)
           ^^^^^^^^^^^^^^^^^^^^^^^^^^^^^^^^^^^^^^^^^^^^^^^^^^^^^^^^^^^^^^^^^^^^^^^
  File "C:\Users\prana\AppData\Local\Programs\Python\Python312\Lib\site-packages\requests\sessions.py", line 589, in request
    resp = self.send(prep, **send_kwargs)
           ^^^^^^^^^^^^^^^^^^^^^^^^^^^^^^
  File "C:\Users\prana\AppData\Local\Programs\Python\Python312\Lib\site-packages\requests\sessions.py", line 703, in send
    r = adapter.send(request, **kwargs)
        ^^^^^^^^^^^^^^^^^^^^^^^^^^^^^^^
  File "C:\Users\prana\AppData\Local\Programs\Python\Python312\Lib\site-packages\requests\adapters.py", line 700, in send
    raise ConnectionError(e, request=request)
requests.exceptions.ConnectionError: HTTPConnectionPool(host='localhost', port=5000): Max retries exceeded with url: /api/2.0/mlflow/experiments/get-by-name?experiment_name=Feature_Selection_Pipeline (Caused by NewConnectionError('<urllib3.connection.HTTPConnection object at 0x000001BA58591910>: Failed to establish a new connection: [WinError 10061] No connection could be made because the target machine actively refused it'))

During handling of the above exception, another exception occurred:

Traceback (most recent call last):
  File "C:\Users\prana\OneDrive\Desktop\Application\run_fs.py", line 28, in run_feature_selection
    init_mlflow()
  File "C:\Users\prana\OneDrive\Desktop\Application\mlflow_utils.py", line 10, in init_mlflow
    experiment = mlflow.get_experiment_by_name(experiment_name)
                 ^^^^^^^^^^^^^^^^^^^^^^^^^^^^^^^^^^^^^^^^^^^^^^
  File "C:\Users\prana\AppData\Local\Programs\Python\Python312\Lib\site-packages\mlflow\tracking\fluent.py", line 1678, in get_experiment_by_name
    return MlflowClient().get_experiment_by_name(name)
           ^^^^^^^^^^^^^^^^^^^^^^^^^^^^^^^^^^^^^^^^^^^
  File "C:\Users\prana\AppData\Local\Programs\Python\Python312\Lib\site-packages\mlflow\tracking\client.py", line 1698, in get_experiment_by_name
    return self._tracking_client.get_experiment_by_name(name)
           ^^^^^^^^^^^^^^^^^^^^^^^^^^^^^^^^^^^^^^^^^^^^^^^^^^
  File "C:\Users\prana\AppData\Local\Programs\Python\Python312\Lib\site-packages\mlflow\tracking\_tracking_service\client.py", line 586, in get_experiment_by_name
    return self.store.get_experiment_by_name(name)
           ^^^^^^^^^^^^^^^^^^^^^^^^^^^^^^^^^^^^^^^
  File "C:\Users\prana\AppData\Local\Programs\Python\Python312\Lib\site-packages\mlflow\store\tracking\rest_store.py", line 641, in get_experiment_by_name
    response_proto = self._call_endpoint(GetExperimentByName, req_body)
                     ^^^^^^^^^^^^^^^^^^^^^^^^^^^^^^^^^^^^^^^^^^^^^^^^^^
  File "C:\Users\prana\AppData\Local\Programs\Python\Python312\Lib\site-packages\mlflow\store\tracking\rest_store.py", line 90, in _call_endpoint
    return call_endpoint(self.get_host_creds(), endpoint, method, json_body, response_proto)
           ^^^^^^^^^^^^^^^^^^^^^^^^^^^^^^^^^^^^^^^^^^^^^^^^^^^^^^^^^^^^^^^^^^^^^^^^^^^^^^^^^
  File "C:\Users\prana\AppData\Local\Programs\Python\Python312\Lib\site-packages\mlflow\utils\rest_utils.py", line 387, in call_endpoint
    response = http_request(**call_kwargs)
               ^^^^^^^^^^^^^^^^^^^^^^^^^^^
  File "C:\Users\prana\AppData\Local\Programs\Python\Python312\Lib\site-packages\mlflow\utils\rest_utils.py", line 204, in http_request
    raise MlflowException(f"API request to {url} failed with exception {e}")
mlflow.exceptions.MlflowException: API request to http://localhost:5000/api/2.0/mlflow/experiments/get-by-name failed with exception HTTPConnectionPool(host='localhost', port=5000): Max retries exceeded with url: /api/2.0/mlflow/experiments/get-by-name?experiment_name=Feature_Selection_Pipeline (Caused by NewConnectionError('<urllib3.connection.HTTPConnection object at 0x000001BA58591910>: Failed to establish a new connection: [WinError 10061] No connection could be made because the target machine actively refused it'))

2025-04-27 17:20:42 - INFO - Default parameters: {'train_file': 'input data/dev.csv', 'validation_file': 'input data/oos.csv', 'test_file': 'input data/oot.csv', 'target_column': 'Class', 'train_on': 'normal', 'feature_selection': 'fpi', 'feature_threshold': 0.1, 'model_threshold': 0, 'model': 'LogisticRegression', 'cross_validation': 5, 'autoencoder': {'ratios': [0.8, 0.5, 0.2], 'epochs': 10, 'batch_size': 32, 'dropout': 0.1, 'hidden_activation': 'selu', 'optimizer': 'adam', 'loss': 'mse'}, 'model_params': {'C': 0.01, 'penalty': 'l2', 'solver': 'lbfgs', 'max_iter': 200, 'random_state': 42}}
2025-04-27 17:20:44 - INFO - Running initial feature selection using default parameters
2025-04-27 17:23:37 - INFO - Feature selection completed. Dropped features: ['V1', 'V4', 'V9', 'V12', 'V18', 'V20', 'V22', 'V24', 'V27', 'Amount']
2025-04-27 17:50:57 - INFO - Default parameters: {'train_file': 'input data/dev.csv', 'validation_file': 'input data/oos.csv', 'test_file': 'input data/oot.csv', 'target_column': 'Class', 'train_on': 'normal', 'feature_selection': 'fpi', 'feature_threshold': 0.1, 'model_threshold': 0, 'model': 'LogisticRegression', 'cross_validation': 5, 'autoencoder': {'ratios': [0.8, 0.5, 0.2], 'epochs': 10, 'batch_size': 32, 'dropout': 0.1, 'hidden_activation': 'selu', 'optimizer': 'adam', 'loss': 'mse'}, 'model_params': {'C': 0.01, 'penalty': 'l2', 'solver': 'lbfgs', 'max_iter': 200, 'random_state': 42}}
2025-04-27 17:50:59 - INFO - Running initial feature selection using default parameters
2025-04-27 17:53:37 - ERROR - Error during feature selection: must be real number, not str
2025-04-27 17:53:37 - ERROR - Traceback (most recent call last):
  File "C:\Users\prana\OneDrive\Desktop\Application\run_fs.py", line 47, in run_feature_selection
    log_metrics_and_artifacts(
  File "C:\Users\prana\OneDrive\Desktop\Application\mlflow_utils.py", line 92, in log_metrics_and_artifacts
    mlflow.log_metric("Features Dropped", str(features_dropped))
  File "C:\Users\prana\AppData\Local\Programs\Python\Python312\Lib\site-packages\mlflow\tracking\fluent.py", line 923, in log_metric
    return MlflowClient().log_metric(
           ^^^^^^^^^^^^^^^^^^^^^^^^^^
  File "C:\Users\prana\AppData\Local\Programs\Python\Python312\Lib\site-packages\mlflow\tracking\client.py", line 1967, in log_metric
    return self._tracking_client.log_metric(
           ^^^^^^^^^^^^^^^^^^^^^^^^^^^^^^^^^
  File "C:\Users\prana\AppData\Local\Programs\Python\Python312\Lib\site-packages\mlflow\tracking\_tracking_service\client.py", line 667, in log_metric
    self.store.log_metric(run_id, metric)
  File "C:\Users\prana\AppData\Local\Programs\Python\Python312\Lib\site-packages\mlflow\store\tracking\rest_store.py", line 517, in log_metric
    LogMetric(
TypeError: must be real number, not str

2025-04-27 17:53:37 - ERROR - Error in setup: must be real number, not str
2025-04-27 17:53:37 - ERROR - Traceback (most recent call last):
  File "C:\Users\prana\OneDrive\Desktop\Application\run_fs.py", line 47, in run_feature_selection
    log_metrics_and_artifacts(
  File "C:\Users\prana\OneDrive\Desktop\Application\mlflow_utils.py", line 92, in log_metrics_and_artifacts
    mlflow.log_metric("Features Dropped", str(features_dropped))
  File "C:\Users\prana\AppData\Local\Programs\Python\Python312\Lib\site-packages\mlflow\tracking\fluent.py", line 923, in log_metric
    return MlflowClient().log_metric(
           ^^^^^^^^^^^^^^^^^^^^^^^^^^
  File "C:\Users\prana\AppData\Local\Programs\Python\Python312\Lib\site-packages\mlflow\tracking\client.py", line 1967, in log_metric
    return self._tracking_client.log_metric(
           ^^^^^^^^^^^^^^^^^^^^^^^^^^^^^^^^^
  File "C:\Users\prana\AppData\Local\Programs\Python\Python312\Lib\site-packages\mlflow\tracking\_tracking_service\client.py", line 667, in log_metric
    self.store.log_metric(run_id, metric)
  File "C:\Users\prana\AppData\Local\Programs\Python\Python312\Lib\site-packages\mlflow\store\tracking\rest_store.py", line 517, in log_metric
    LogMetric(
TypeError: must be real number, not str

2025-04-27 18:01:07 - INFO - Default parameters: {'train_file': 'input data/dev.csv', 'validation_file': 'input data/oos.csv', 'test_file': 'input data/oot.csv', 'target_column': 'Class', 'train_on': 'normal', 'feature_selection': 'fpi', 'feature_threshold': 0.1, 'model_threshold': 0, 'model': 'LogisticRegression', 'cross_validation': 5, 'autoencoder': {'ratios': [0.8, 0.5, 0.2], 'epochs': 10, 'batch_size': 32, 'dropout': 0.1, 'hidden_activation': 'selu', 'optimizer': 'adam', 'loss': 'mse'}, 'model_params': {'C': 0.01, 'penalty': 'l2', 'solver': 'lbfgs', 'max_iter': 200, 'random_state': 42}}
2025-04-27 18:01:10 - INFO - Running initial feature selection using default parameters
2025-04-27 18:04:16 - INFO - Feature selection completed. Dropped features: ['V1', 'V4', 'V9', 'V21', 'V26', 'Amount']
2025-04-29 17:28:14 - INFO - Default parameters: {'train_file': 'input data/dev.csv', 'validation_file': 'input data/oos.csv', 'test_file': 'input data/oot.csv', 'target_column': 'Class', 'train_on': 'normal', 'feature_selection': 'fpi', 'feature_threshold': 0.1, 'model_threshold': 0, 'model': 'LogisticRegression', 'cross_validation': 5, 'autoencoder': {'ratios': [0.8, 0.5, 0.2], 'epochs': 10, 'batch_size': 32, 'dropout': 0.1, 'hidden_activation': 'selu', 'optimizer': 'adam', 'loss': 'mse'}, 'model_params': {'C': 0.01, 'penalty': 'l2', 'solver': 'lbfgs', 'max_iter': 200, 'random_state': 42}}
2025-04-29 17:28:17 - INFO - Running initial feature selection using default parameters
2025-04-29 17:31:00 - ERROR - Error during feature selection: 'autoencoder_F_history'
2025-04-29 17:31:00 - ERROR - Traceback (most recent call last):
  File "C:\Users\prana\OneDrive\Desktop\Application\run_fs.py", line 59, in run_feature_selection
    mlflow.log_metric("fraud_autoencoder_final_loss", results["autoencoder_F_history"].history['loss'][-1])
                                                      ~~~~~~~^^^^^^^^^^^^^^^^^^^^^^^^^
KeyError: 'autoencoder_F_history'

2025-04-29 17:31:00 - ERROR - Error in setup: 'autoencoder_F_history'
2025-04-29 17:31:00 - ERROR - Traceback (most recent call last):
  File "C:\Users\prana\OneDrive\Desktop\Application\run_fs.py", line 59, in run_feature_selection
    mlflow.log_metric("fraud_autoencoder_final_loss", results["autoencoder_F_history"].history['loss'][-1])
                                                      ~~~~~~~^^^^^^^^^^^^^^^^^^^^^^^^^
KeyError: 'autoencoder_F_history'

2025-04-29 17:35:47 - INFO - Default parameters: {'train_file': 'input data/dev.csv', 'validation_file': 'input data/oos.csv', 'test_file': 'input data/oot.csv', 'target_column': 'Class', 'train_on': 'normal', 'feature_selection': 're', 'feature_threshold': 0.1, 'model_threshold': 0, 'model': 'LogisticRegression', 'cross_validation': 5, 'autoencoder': {'ratios': [0.8, 0.5, 0.2], 'epochs': 10, 'batch_size': 32, 'dropout': 0.1, 'hidden_activation': 'selu', 'optimizer': 'adam', 'loss': 'mse'}, 'model_params': {'C': 0.01, 'penalty': 'l2', 'solver': 'lbfgs', 'max_iter': 200, 'random_state': 42}}
2025-04-29 17:35:50 - INFO - Running initial feature selection using default parameters
2025-04-29 17:37:07 - INFO - Feature selection completed. Dropped features: ['V23', 'V28']
